2020-05-05 15:39:32,332 [mysql_sunck][thread:40768] D:/python3/tornadoFrame1/mysql/mysql_sunck.py[line21][ERROR]:172.20.5.69test连接失败
2020-05-05 15:39:32,335 [mysql_sunck][thread:40768] D:/python3/tornadoFrame1/mysql/mysql_sunck.py[line22][ERROR]:(2003, "Can't connect to MySQL server on '172.20.5.69' (timed out)")
Traceback (most recent call last):
  File "D:\python3\project\venv\lib\site-packages\pymysql\connections.py", line 583, in connect
    **kwargs)
  File "D:\python3\program\lib\socket.py", line 727, in create_connection
    raise err
  File "D:\python3\program\lib\socket.py", line 716, in create_connection
    sock.connect(sa)
socket.timeout: timed out

During handling of the above exception, another exception occurred:

Traceback (most recent call last):
  File "D:/python3/tornadoFrame1/mysql/mysql_sunck.py", line 16, in connect
    self.db = pymysql.connect(self.host,self.user,self.passWd,self.dbName)
  File "D:\python3\project\venv\lib\site-packages\pymysql\__init__.py", line 94, in Connect
    return Connection(*args, **kwargs)
  File "D:\python3\project\venv\lib\site-packages\pymysql\connections.py", line 325, in __init__
    self.connect()
  File "D:\python3\project\venv\lib\site-packages\pymysql\connections.py", line 630, in connect
    raise exc
pymysql.err.OperationalError: (2003, "Can't connect to MySQL server on '172.20.5.69' (timed out)")
2020-05-05 15:39:32,336 [mysql_sunck][thread:40768] D:/python3/tornadoFrame1/mysql/mysql_sunck.py[line51][ERROR]:查询失败
2020-05-05 15:39:32,337 [mysql_sunck][thread:40768] D:/python3/tornadoFrame1/mysql/mysql_sunck.py[line52][ERROR]:'SunckMySql' object has no attribute 'cursor'
Traceback (most recent call last):
  File "D:/python3/tornadoFrame1/mysql/mysql_sunck.py", line 47, in get_all
    self.cursor.execute(sql)
AttributeError: 'SunckMySql' object has no attribute 'cursor'
2020-05-05 15:40:21,998 [mysql_sunck][thread:45720] D:/python3/tornadoFrame1/mysql/mysql_sunck.py[line21][ERROR]:172.20.5.69'@'test连接失败
2020-05-05 15:40:21,999 [mysql_sunck][thread:45720] D:/python3/tornadoFrame1/mysql/mysql_sunck.py[line22][ERROR]:(2003, "Can't connect to MySQL server on '172.20.5.69' (timed out)")
Traceback (most recent call last):
  File "D:\python3\project\venv\lib\site-packages\pymysql\connections.py", line 583, in connect
    **kwargs)
  File "D:\python3\program\lib\socket.py", line 727, in create_connection
    raise err
  File "D:\python3\program\lib\socket.py", line 716, in create_connection
    sock.connect(sa)
socket.timeout: timed out

During handling of the above exception, another exception occurred:

Traceback (most recent call last):
  File "D:/python3/tornadoFrame1/mysql/mysql_sunck.py", line 16, in connect
    self.db = pymysql.connect(self.host,self.user,self.passWd,self.dbName)
  File "D:\python3\project\venv\lib\site-packages\pymysql\__init__.py", line 94, in Connect
    return Connection(*args, **kwargs)
  File "D:\python3\project\venv\lib\site-packages\pymysql\connections.py", line 325, in __init__
    self.connect()
  File "D:\python3\project\venv\lib\site-packages\pymysql\connections.py", line 630, in connect
    raise exc
pymysql.err.OperationalError: (2003, "Can't connect to MySQL server on '172.20.5.69' (timed out)")
2020-05-05 15:40:22,000 [mysql_sunck][thread:45720] D:/python3/tornadoFrame1/mysql/mysql_sunck.py[line51][ERROR]:查询失败
2020-05-05 15:40:22,000 [mysql_sunck][thread:45720] D:/python3/tornadoFrame1/mysql/mysql_sunck.py[line52][ERROR]:'SunckMySql' object has no attribute 'cursor'
Traceback (most recent call last):
  File "D:/python3/tornadoFrame1/mysql/mysql_sunck.py", line 47, in get_all
    self.cursor.execute(sql)
AttributeError: 'SunckMySql' object has no attribute 'cursor'
2020-05-05 15:40:46,359 [mysql_sunck][thread:48764] D:/python3/tornadoFrame1/mysql/mysql_sunck.py[line21][ERROR]:172.20.5.69@test连接失败
2020-05-05 15:40:46,359 [mysql_sunck][thread:48764] D:/python3/tornadoFrame1/mysql/mysql_sunck.py[line22][ERROR]:(2003, "Can't connect to MySQL server on '172.20.5.69' (timed out)")
Traceback (most recent call last):
  File "D:\python3\project\venv\lib\site-packages\pymysql\connections.py", line 583, in connect
    **kwargs)
  File "D:\python3\program\lib\socket.py", line 727, in create_connection
    raise err
  File "D:\python3\program\lib\socket.py", line 716, in create_connection
    sock.connect(sa)
socket.timeout: timed out

During handling of the above exception, another exception occurred:

Traceback (most recent call last):
  File "D:/python3/tornadoFrame1/mysql/mysql_sunck.py", line 16, in connect
    self.db = pymysql.connect(self.host,self.user,self.passWd,self.dbName)
  File "D:\python3\project\venv\lib\site-packages\pymysql\__init__.py", line 94, in Connect
    return Connection(*args, **kwargs)
  File "D:\python3\project\venv\lib\site-packages\pymysql\connections.py", line 325, in __init__
    self.connect()
  File "D:\python3\project\venv\lib\site-packages\pymysql\connections.py", line 630, in connect
    raise exc
pymysql.err.OperationalError: (2003, "Can't connect to MySQL server on '172.20.5.69' (timed out)")
2020-05-05 15:40:46,361 [mysql_sunck][thread:48764] D:/python3/tornadoFrame1/mysql/mysql_sunck.py[line51][ERROR]:查询失败
2020-05-05 15:40:46,361 [mysql_sunck][thread:48764] D:/python3/tornadoFrame1/mysql/mysql_sunck.py[line52][ERROR]:'SunckMySql' object has no attribute 'cursor'
Traceback (most recent call last):
  File "D:/python3/tornadoFrame1/mysql/mysql_sunck.py", line 47, in get_all
    self.cursor.execute(sql)
AttributeError: 'SunckMySql' object has no attribute 'cursor'
